Workbook
Name Canby_Molalla_Dustin: MGR!$A$212:$O$224
Name Div_2_Wireless: MGR!$A$4:$O$37
Name Stayton_Peoples_Dennis: MGR!#REF!

Sheet MGR
A1: North Sky Manager Review - P&L by Project - June FY27 through Week 2.
A2: Contract Name | B2: Contract # | C2: Former # | D2: Direct Labor Hours | E2: PTD Revenue | F2: PTD Adj Revenue | G2: PTD Costs | H2: PTD Adj Costs | I2: PTD Margin | J2: PTD % | K2: Unbilled (WIP) | L2: Accrued Revenue |$4000+| | M2: Accrued Costs |$4000+| | N2: Profit Center Management Comments | O2: Ross' Comments | P2: JTD Revenue | Q2: JTD Adj Revenue | R2: JTD Costs | S2: JTD Adj Costs | T2: JTD Margin | U2: JTD Margin %
A3: Division 2 - Wireless & Installation
A4: Div 2 - Wireless - Nate
A5: =VLOOKUP(B5,'SAP Contracts'!A:J,10,FALSE) -> American Tower Corporation-WA | B5: =VLOOKUP(C5,'Active North Sky Projects'!C:D,2,FALSE) -> 21171 | C5: 2484115 | D5: =IFERROR(VLOOKUP(B5,'MTD Hours Paste Data'!A:C,3,FALSE),"") -> 55.36 | E5: =IFERROR(VLOOKUP(B5,'ACDOCA - Paste Data'!B:G,6,FALSE),0) -> 10001 | F5: =E5 +L5 -> 10001 | G5: =IFERROR(VLOOKUP(B5,'ACDOCA - Paste Data'!B:H,7,FALSE),0) -> 9014.15 | H5: =G5+M5 -> 9014.15 | I5: =F5-H5 -> 986.85 | J5: =IFERROR(I5/F5,0) -> 0.098675132 | K5: =IFERROR(VLOOKUP(B5,'WIP - Paste Data'!B:E,4,FALSE),"") -> 10001 | P5: =IFERROR(VLOOKUP(B5,'JTD Paste Data'!A:B,2,FALSE),"0") -> 37883.74 | Q5: =SUM(P5+L5) -> 37883.74 | R5: =IFERROR(VLOOKUP(B5,'JTD Paste Data'!A:C,3,FALSE),"0") -> 33776.75 | S5: =SUM(R5+M5) -> 33776.75 | T5: =SUM(Q5-S5) -> 4106.99 | U5: =IFERROR(T5/Q5,0) -> 0.10841036
A6: =VLOOKUP(B6,'SAP Contracts'!A:J,10,FALSE) -> Astound - WA - Drone Work | B6: =VLOOKUP(C6,'Active North Sky Projects'!C:D,2,FALSE) -> 21053 | C6: 2486024 | D6: =IFERROR(VLOOKUP(B6,'MTD Hours Paste Data'!A:C,3,FALSE),"") | E6: =IFERROR(VLOOKUP(B6,'ACDOCA - Paste Data'!B:G,6,FALSE),0) -> 0 | F6: =E6 +L6 -> 0 | G6: =IFERROR(VLOOKUP(B6,'ACDOCA - Paste Data'!B:H,7,FALSE),0) -> 0 | H6: =G6+M6 -> 0 | I6: =F6-H6 -> 0 | J6: =IFERROR(I6/F6,0) -> 0 | K6: =IFERROR(VLOOKUP(B6,'WIP - Paste Data'!B:E,4,FALSE),"") | P6: =IFERROR(VLOOKUP(B6,'JTD Paste Data'!A:B,2,FALSE),"0") -> 6500 | Q6: =SUM(P6+L6) -> 6500 | R6: =IFERROR(VLOOKUP(B6,'JTD Paste Data'!A:C,3,FALSE),"0") -> 4309.11 | S6: =SUM(R6+M6) -> 4309.11 | T6: =SUM(Q6-S6) -> 2190.89 | U6: =IFERROR(T6/Q6,0) -> 0.33706
A7: =VLOOKUP(B7,'SAP Contracts'!A:J,10,FALSE) -> Astound - WA - Lewis River | B7: =VLOOKUP(C7,'Active North Sky Projects'!C:D,2,FALSE) -> 21395 | C7: 2486022 | D7: =IFERROR(VLOOKUP(B7,'MTD Hours Paste Data'!A:C,3,FALSE),"") | E7: =IFERROR(VLOOKUP(B7,'ACDOCA - Paste Data'!B:G,6,FALSE),0) -> 0 | F7: =E7 +L7 -> 0 | G7: =IFERROR(VLOOKUP(B7,'ACDOCA - Paste Data'!B:H,7,FALSE),0) -> 0 | H7: =G7+M7 -> 0 | I7: =F7-H7 -> 0 | J7: =IFERROR(I7/F7,0) -> 0 | K7: =IFERROR(VLOOKUP(B7,'WIP - Paste Data'!B:E,4,FALSE),"") | P7: =IFERROR(VLOOKUP(B7,'JTD Paste Data'!A:B,2,FALSE),"0") -> 121030 | Q7: =SUM(P7+L7) -> 121030 | R7: =IFERROR(VLOOKUP(B7,'JTD Paste Data'!A:C,3,FALSE),"0") -> 94039.27 | S7: =SUM(R7+M7) -> 94039.27 | T7: =SUM(Q7-S7) -> 26990.73 | U7: =IFERROR(T7/Q7,0) -> 0.22300859
A8: =VLOOKUP(B8,'SAP Contracts'!A:J,10,FALSE) -> Astound - WA- Oak Harbor | B8: =VLOOKUP(C8,'Active North Sky Projects'!C:D,2,FALSE) -> 21387 | C8: 2486021 | D8: =IFERROR(VLOOKUP(B8,'MTD Hours Paste Data'!A:C,3,FALSE),"") | E8: =IFERROR(VLOOKUP(B8,'ACDOCA - Paste Data'!B:G,6,FALSE),0) -> 0 | F8: =E8 +L8 -> 0 | G8: =IFERROR(VLOOKUP(B8,'ACDOCA - Paste Data'!B:H,7,FALSE),0) -> 0 | H8: =G8+M8 -> 0 | I8: =F8-H8 -> 0 | J8: =IFERROR(I8/F8,0) -> 0 | K8: =IFERROR(VLOOKUP(B8,'WIP - Paste Data'!B:E,4,FALSE),"") -> 8400 | P8: =IFERROR(VLOOKUP(B8,'JTD Paste Data'!A:B,2,FALSE),"0") -> 8400 | Q8: =SUM(P8+L8) -> 8400 | R8: =IFERROR(VLOOKUP(B8,'JTD Paste Data'!A:C,3,FALSE),"0") -> 6564.52 | S8: =SUM(R8+M8) -> 6564.52 | T8: =SUM(Q8-S8) -> 1835.48 | U8: =IFERROR(T8/Q8,0) -> 0.21850952
A9: =VLOOKUP(B9,'SAP Contracts'!A:J,10,FALSE) -> Colville Tribes - MAT Solar | B9: =VLOOKUP(C9,'Active North Sky Projects'!C:D,2,FALSE) -> 21415 | C9: 2486026 | D9: =IFERROR(VLOOKUP(B9,'MTD Hours Paste Data'!A:C,3,FALSE),"") -> 0 | E9: =IFERROR(VLOOKUP(B9,'ACDOCA - Paste Data'!B:G,6,FALSE),0) -> 307 | F9: =E9 +L9 -> 307 | G9: =IFERROR(VLOOKUP(B9,'ACDOCA - Paste Data'!B:H,7,FALSE),0) -> 402.9 | H9: =G9+M9 -> 402.9 | I9: =F9-H9 -> -95.9 | J9: =IFERROR(I9/F9,0) -> -0.31237785 | K9: =IFERROR(VLOOKUP(B9,'WIP - Paste Data'!B:E,4,FALSE),"") -> 308463 | P9: =IFERROR(VLOOKUP(B9,'JTD Paste Data'!A:B,2,FALSE),"0") -> 308463 | Q9: =SUM(P9+L9) -> 308463 | R9: =IFERROR(VLOOKUP(B9,'JTD Paste Data'!A:C,3,FALSE),"0") -> 318316.45 | S9: =SUM(R9+M9) -> 318316.45 | T9: =SUM(Q9-S9) -> -9853.45 | U9: =IFERROR(T9/Q9,0) -> -0.031943702
A10: =VLOOKUP(B10,'SAP Contracts'!A:J,10,FALSE) -> Colville Tribes - Wireless Maintenance | B10: =VLOOKUP(C10,'Active North Sky Projects'!C:D,2,FALSE) -> 21412 | C10: 2484120 | D10: =IFERROR(VLOOKUP(B10,'MTD Hours Paste Data'!A:C,3,FALSE),"") -> 0 | E10: =IFERROR(VLOOKUP(B10,'ACDOCA - Paste Data'!B:G,6,FALSE),0) -> 0 | F10: =E10 +L10 -> 0 | G10: =IFERROR(VLOOKUP(B10,'ACDOCA - Paste Data'!B:H,7,FALSE),0) -> 0 | H10: =G10+M10 -> 0 | I10: =F10-H10 -> 0 | J10: =IFERROR(I10/F10,0) -> 0 | K10: =IFERROR(VLOOKUP(B10,'WIP - Paste Data'!B:E,4,FALSE),"") -> 1200 | P10: =IFERROR(VLOOKUP(B10,'JTD Paste Data'!A:B,2,FALSE),"0") -> 28840.56 | Q10: =SUM(P10+L10) -> 28840.56 | R10: =IFERROR(VLOOKUP(B10,'JTD Paste Data'!A:C,3,FALSE),"0") -> 23560.93 | S10: =SUM(R10+M10) -> 23560.93 | T10: =SUM(Q10-S10) -> 5279.63 | U10: =IFERROR(T10/Q10,0) -> 0.18306267
A11: =VLOOKUP(B11,'SAP Contracts'!A:J,10,FALSE) -> Colville Tribes - Wireless Sites | B11: =VLOOKUP(C11,'Active North Sky Projects'!C:D,2,FALSE) -> 21407 | C11: 2486025 | D11: =IFERROR(VLOOKUP(B11,'MTD Hours Paste Data'!A:C,3,FALSE),"") -> 338.1 | E11: =IFERROR(VLOOKUP(B11,'ACDOCA - Paste Data'!B:G,6,FALSE),0) -> 115227 | F11: =E11 +L11 -> 115227 | G11: =IFERROR(VLOOKUP(B11,'ACDOCA - Paste Data'!B:H,7,FALSE),0) -> 134086.4 | H11: =G11+M11 -> 134086.4 | I11: =F11-H11 -> -18859.4 | J11: =IFERROR(I11/F11,0) -> -0.16367171 | K11: =IFERROR(VLOOKUP(B11,'WIP - Paste Data'!B:E,4,FALSE),"") -> 524157.86 | P11: =IFERROR(VLOOKUP(B11,'JTD Paste Data'!A:B,2,FALSE),"0") -> 1524157.9 | Q11: =SUM(P11+L11) -> 1524157.9 | R11: =IFERROR(VLOOKUP(B11,'JTD Paste Data'!A:C,3,FALSE),"0") -> 1498782.8 | S11: =SUM(R11+M11) -> 1498782.8 | T11: =SUM(Q11-S11) -> 25375.05 | U11: =IFERROR(T11/Q11,0) -> 0.016648571
A12: =VLOOKUP(B12,'SAP Contracts'!A:J,10,FALSE) -> Crown Castle - ID | B12: =VLOOKUP(C12,'Active North Sky Projects'!C:D,2,FALSE) -> 21191 | C12: 2136014 | D12: =IFERROR(VLOOKUP(B12,'MTD Hours Paste Data'!A:C,3,FALSE),"") -> 0 | E12: =IFERROR(VLOOKUP(B12,'ACDOCA - Paste Data'!B:G,6,FALSE),0) -> 0 | F12: =E12 +L12 -> 0 | G12: =IFERROR(VLOOKUP(B12,'ACDOCA - Paste Data'!B:H,7,FALSE),0) -> 0 | H12: =G12+M12 -> 0 | I12: =F12-H12 -> 0 | J12: =IFERROR(I12/F12,0) -> 0 | K12: =IFERROR(VLOOKUP(B12,'WIP - Paste Data'!B:E,4,FALSE),"") | P12: =IFERROR(VLOOKUP(B12,'JTD Paste Data'!A:B,2,FALSE),"0") -> 14864.2 | Q12: =SUM(P12+L12) -> 14864.2 | R12: =IFERROR(VLOOKUP(B12,'JTD Paste Data'!A:C,3,FALSE),"0") -> 14299.7 | S12: =SUM(R12+M12) -> 14299.7 | T12: =SUM(Q12-S12) -> 564.5 | U12: =IFERROR(T12/Q12,0) -> 0.037977153
A13: =VLOOKUP(B13,'SAP Contracts'!A:J,10,FALSE) -> Spokane Tribe - WA | B13: =VLOOKUP(C13,'Active North Sky Projects'!C:D,2,FALSE) -> 21057 | C13: 2486030 | D13: =IFERROR(VLOOKUP(B13,'MTD Hours Paste Data'!A:C,3,FALSE),"") -> 0 | E13: =IFERROR(VLOOKUP(B13,'ACDOCA - Paste Data'!B:G,6,FALSE),0) -> 0 | F13: =E13 +L13 -> 0 | G13: =IFERROR(VLOOKUP(B13,'ACDOCA - Paste Data'!B:H,7,FALSE),0) -> 0 | H13: =G13+M13 -> 0 | I13: =F13-H13 -> 0 | J13: =IFERROR(I13/F13,0) -> 0 | K13: =IFERROR(VLOOKUP(B13,'WIP - Paste Data'!B:E,4,FALSE),"") -> 24462.22 | P13: =IFERROR(VLOOKUP(B13,'JTD Paste Data'!A:B,2,FALSE),"0") -> 48099.55 | Q13: =SUM(P13+L13) -> 48099.55 | R13: =IFERROR(VLOOKUP(B13,'JTD Paste Data'!A:C,3,FALSE),"0") -> 44805.26 | S13: =SUM(R13+M13) -> 44805.26 | T13: =SUM(Q13-S13) -> 3294.29 | U13: =IFERROR(T13/Q13,0) -> 0.068488998
A14: =VLOOKUP(B14,'SAP Contracts'!A:J,10,FALSE) -> T-Mobile- Eastern OR Market 2025-2026 | B14: =VLOOKUP(C14,'Active North Sky Projects'!C:D,2,FALSE) -> 21288 | C14: 2386051 | D14: =IFERROR(VLOOKUP(B14,'MTD Hours Paste Data'!A:C,3,FALSE),"") -> 0 | E14: =IFERROR(VLOOKUP(B14,'ACDOCA - Paste Data'!B:G,6,FALSE),0) -> 0 | F14: =E14 +L14 -> 0 | G14: =IFERROR(VLOOKUP(B14,'ACDOCA - Paste Data'!B:H,7,FALSE),0) -> 0 | H14: =G14+M14 -> 0 | I14: =F14-H14 -> 0 | J14: =IFERROR(I14/F14,0) -> 0 | K14: =IFERROR(VLOOKUP(B14,'WIP - Paste Data'!B:E,4,FALSE),"") | P14: =IFERROR(VLOOKUP(B14,'JTD Paste Data'!A:B,2,FALSE),"0") -> 77676.8 | Q14: =SUM(P14+L14) -> 77676.8 | R14: =IFERROR(VLOOKUP(B14,'JTD Paste Data'!A:C,3,FALSE),"0") -> 79399.49 | S14: =SUM(R14+M14) -> 79399.49 | T14: =SUM(Q14-S14) -> -1722.69 | U14: =IFERROR(T14/Q14,0) -> -0.022177664
A15: T-Mobile-Eastern OR Market 2026 | B15: 21922 | C15: 2386061 | D15: =IFERROR(VLOOKUP(B15,'MTD Hours Paste Data'!A:C,3,FALSE),"") | E15: =IFERROR(VLOOKUP(B15,'ACDOCA - Paste Data'!B:G,6,FALSE),0) -> 44607.78 | F15: =E15 +L15 -> 44607.78 | G15: =IFERROR(VLOOKUP(B15,'ACDOCA - Paste Data'!B:H,7,FALSE),0) -> 29107.6 | H15: =G15+M15 -> 29107.6 | I15: =F15-H15 -> 15500.18 | J15: =IFERROR(I15/F15,0) -> 0.34747705 | K15: =IFERROR(VLOOKUP(B15,'WIP - Paste Data'!B:E,4,FALSE),"") -> 86609.59 | P15: =IFERROR(VLOOKUP(B15,'JTD Paste Data'!A:B,2,FALSE),"0") -> 144125.82 | Q15: =SUM(P15+L15) -> 144125.82 | R15: =IFERROR(VLOOKUP(B15,'JTD Paste Data'!A:C,3,FALSE),"0") -> 86076.79 | S15: =SUM(R15+M15) -> 86076.79 | T15: =SUM(Q15-S15) -> 58049.03 | U15: =IFERROR(T15/Q15,0) -> 0.40276635
A16: T-Mobile-Idaho Market 2026 | B16: =VLOOKUP(C16,'Active North Sky Projects'!C:D,2,FALSE) -> 21250 | C16: 2136060 | D16: =IFERROR(VLOOKUP(B16,'MTD Hours Paste Data'!A:C,3,FALSE),"") -> 18.01 | E16: =IFERROR(VLOOKUP(B16,'ACDOCA - Paste Data'!B:G,6,FALSE),0) -> 3336 | F16: =E16 +L16 -> 3336 | G16: =IFERROR(VLOOKUP(B16,'ACDOCA - Paste Data'!B:H,7,FALSE),0) -> 2974.03 | H16: =G16+M16 -> 2974.03 | I16: =F16-H16 -> 361.97 | J16: =IFERROR(I16/F16,0) -> 0.1085042 | K16: =IFERROR(VLOOKUP(B16,'WIP - Paste Data'!B:E,4,FALSE),"") -> 3336 | P16: =IFERROR(VLOOKUP(B16,'JTD Paste Data'!A:B,2,FALSE),"0") -> 175988 | Q16: =SUM(P16+L16) -> 175988 | R16: =IFERROR(VLOOKUP(B16,'JTD Paste Data'!A:C,3,FALSE),"0") -> 151343.1 | S16: =SUM(R16+M16) -> 151343.1 | T16: =SUM(Q16-S16) -> 24644.9 | U16: =IFERROR(T16/Q16,0) -> 0.14003739
A17: =VLOOKUP(B17,'SAP Contracts'!A:J,10,FALSE) -> T-Mobile-Idaho Market 2025-2026 | B17: =VLOOKUP(C17,'Active North Sky Projects'!C:D,2,FALSE) -> 21513 | C17: 2136050 | D17: =IFERROR(VLOOKUP(B17,'MTD Hours Paste Data'!A:C,3,FALSE),"") -> 0 | E17: =IFERROR(VLOOKUP(B17,'ACDOCA - Paste Data'!B:G,6,FALSE),0) -> 0 | F17: =E17 +L17 -> 0 | G17: =IFERROR(VLOOKUP(B17,'ACDOCA - Paste Data'!B:H,7,FALSE),0) -> 0 | H17: =G17+M17 -> 0 | I17: =F17-H17 -> 0 | J17: =IFERROR(I17/F17,0) -> 0 | K17: =IFERROR(VLOOKUP(B17,'WIP - Paste Data'!B:E,4,FALSE),"") | P17: =IFERROR(VLOOKUP(B17,'JTD Paste Data'!A:B,2,FALSE),"0") -> 615365.66 | Q17: =SUM(P17+L17) -> 615365.66 | R17: =IFERROR(VLOOKUP(B17,'JTD Paste Data'!A:C,3,FALSE),"0") -> 595218.44 | S17: =SUM(R17+M17) -> 595218.44 | T17: =SUM(Q17-S17) -> 20147.22 | U17: =IFERROR(T17/Q17,0) -> 0.032740241
A18: =VLOOKUP(B18,'SAP Contracts'!A:J,10,FALSE) -> T-Mobile-Portland Market 2024-2025 | B18: =VLOOKUP(C18,'Active North Sky Projects'!C:D,2,FALSE) -> 21223 | C18: 2385009 | D18: =IFERROR(VLOOKUP(B18,'MTD Hours Paste Data'!A:C,3,FALSE),"") | E18: =IFERROR(VLOOKUP(B18,'ACDOCA - Paste Data'!B:G,6,FALSE),0) -> 0 | F18: =E18 +L18 -> 0 | G18: =IFERROR(VLOOKUP(B18,'ACDOCA - Paste Data'!B:H,7,FALSE),0) -> 0 | H18: =G18+M18 -> 0 | I18: =F18-H18 -> 0 | J18: =IFERROR(I18/F18,0) -> 0 | K18: =IFERROR(VLOOKUP(B18,'WIP - Paste Data'!B:E,4,FALSE),"") | P18: =IFERROR(VLOOKUP(B18,'JTD Paste Data'!A:B,2,FALSE),"0") -> 0 | Q18: =SUM(P18+L18) -> 0 | R18: =IFERROR(VLOOKUP(B18,'JTD Paste Data'!A:C,3,FALSE),"0") -> 0 | S18: =SUM(R18+M18) -> 0 | T18: =SUM(Q18-S18) -> 0 | U18: =IFERROR(T18/Q18,0) -> 0
A19: =VLOOKUP(B19,'SAP Contracts'!A:J,10,FALSE) -> T-Mobile-Portland Market 2025-2026 | B19: =VLOOKUP(C19,'Active North Sky Projects'!C:D,2,FALSE) -> 21277 | C19: 2386050 | D19: =IFERROR(VLOOKUP(B19,'MTD Hours Paste Data'!A:C,3,FALSE),"") -> 0 | E19: =IFERROR(VLOOKUP(B19,'ACDOCA - Paste Data'!B:G,6,FALSE),0) -> 0 | F19: =E19 +L19 -> 0 | G19: =IFERROR(VLOOKUP(B19,'ACDOCA - Paste Data'!B:H,7,FALSE),0) -> 0 | H19: =G19+M19 -> 0 | I19: =F19-H19 -> 0 | J19: =IFERROR(I19/F19,0) -> 0 | K19: =IFERROR(VLOOKUP(B19,'WIP - Paste Data'!B:E,4,FALSE),"") -> 16550.89 | P19: =IFERROR(VLOOKUP(B19,'JTD Paste Data'!A:B,2,FALSE),"0") -> 460420.05 | Q19: =SUM(P19+L19) -> 460420.05 | R19: =IFERROR(VLOOKUP(B19,'JTD Paste Data'!A:C,3,FALSE),"0") -> 414578.26 | S19: =SUM(R19+M19) -> 414578.26 | T19: =SUM(Q19-S19) -> 45841.79 | U19: =IFERROR(T19/Q19,0) -> 0.099565147
A20: T-Mobile-Portland Market 2026 | B20: =VLOOKUP(C20,'Active North Sky Projects'!C:D,2,FALSE) -> 21531 | C20: 2386060 | D20: =IFERROR(VLOOKUP(B20,'MTD Hours Paste Data'!A:C,3,FALSE),"") -> 0 | E20: =IFERROR(VLOOKUP(B20,'ACDOCA - Paste Data'!B:G,6,FALSE),0) -> 16846 | F20: =E20 +L20 -> 16846 | G20: =IFERROR(VLOOKUP(B20,'ACDOCA - Paste Data'!B:H,7,FALSE),0) -> 9474.1 | H20: =G20+M20 -> 9474.1 | I20: =F20-H20 -> 7371.9 | J20: =IFERROR(I20/F20,0) -> 0.43760537 | K20: =IFERROR(VLOOKUP(B20,'WIP - Paste Data'!B:E,4,FALSE),"") -> 153342.12 | P20: =IFERROR(VLOOKUP(B20,'JTD Paste Data'!A:B,2,FALSE),"0") -> 415381.62 | Q20: =SUM(P20+L20) -> 415381.62 | R20: =IFERROR(VLOOKUP(B20,'JTD Paste Data'!A:C,3,FALSE),"0") -> 383684.04 | S20: =SUM(R20+M20) -> 383684.04 | T20: =SUM(Q20-S20) -> 31697.58 | U20: =IFERROR(T20/Q20,0) -> 0.076309539
A21: =VLOOKUP(B21,'SAP Contracts'!A:J,10,FALSE) -> T-Mobile-Spokane Market 2025-2026 | B21: =VLOOKUP(C21,'Active North Sky Projects'!C:D,2,FALSE) -> 21159 | C21: 2486051 | D21: =IFERROR(VLOOKUP(B21,'MTD Hours Paste Data'!A:C,3,FALSE),"") -> 0 | E21: =IFERROR(VLOOKUP(B21,'ACDOCA - Paste Data'!B:G,6,FALSE),0) -> 0 | F21: =E21 +L21 -> 0 | G21: =IFERROR(VLOOKUP(B21,'ACDOCA - Paste Data'!B:H,7,FALSE),0) -> 0 | H21: =G21+M21 -> 0 | I21: =F21-H21 -> 0 | J21: =IFERROR(I21/F21,0) -> 0 | K21: =IFERROR(VLOOKUP(B21,'WIP - Paste Data'!B:E,4,FALSE),"") | P21: =IFERROR(VLOOKUP(B21,'JTD Paste Data'!A:B,2,FALSE),"0") -> 606822.98 | Q21: =SUM(P21+L21) -> 606822.98 | R21: =IFERROR(VLOOKUP(B21,'JTD Paste Data'!A:C,3,FALSE),"0") -> 584176.29 | S21: =SUM(R21+M21) -> 584176.29 | T21: =SUM(Q21-S21) -> 22646.69 | U21: =IFERROR(T21/Q21,0) -> 0.037320093
A22: T-Mobile-Spokane Market 2026 | B22: =VLOOKUP(C22,'Active North Sky Projects'!C:D,2,FALSE) -> 21529 | C22: 2486061 | D22: =IFERROR(VLOOKUP(B22,'MTD Hours Paste Data'!A:C,3,FALSE),"") -> 0 | E22: =IFERROR(VLOOKUP(B22,'ACDOCA - Paste Data'!B:G,6,FALSE),0) -> 10124.34 | F22: =E22 +L22 -> 10124.34 | G22: =IFERROR(VLOOKUP(B22,'ACDOCA - Paste Data'!B:H,7,FALSE),0) -> 10718.75 | H22: =G22+M22 -> 10718.75 | I22: =F22-H22 -> -594.41 | J22: =IFERROR(I22/F22,0) -> -0.058710988 | K22: =IFERROR(VLOOKUP(B22,'WIP - Paste Data'!B:E,4,FALSE),"") -> 9165.86 | P22: =IFERROR(VLOOKUP(B22,'JTD Paste Data'!A:B,2,FALSE),"0") -> 338552.68 | Q22: =SUM(P22+L22) -> 338552.68 | R22: =IFERROR(VLOOKUP(B22,'JTD Paste Data'!A:C,3,FALSE),"0") -> 293852.63 | S22: =SUM(R22+M22) -> 293852.63 | T22: =SUM(Q22-S22) -> 44700.05 | U22: =IFERROR(T22/Q22,0) -> 0.13203278
A23: ODOT - Adel Safety Climb | B23: 22025 | C23: N/A | D23: =IFERROR(VLOOKUP(B23,'MTD Hours Paste Data'!A:C,3,FALSE),"") | E23: =IFERROR(VLOOKUP(B23,'ACDOCA - Paste Data'!B:G,6,FALSE),0) -> 0 | F23: =E23 +L23 -> 0 | G23: =IFERROR(VLOOKUP(B23,'ACDOCA - Paste Data'!B:H,7,FALSE),0) -> 0 | H23: =G23+M23 -> 0 | I23: =F23-H23 -> 0 | J23: =IFERROR(I23/F23,0) -> 0 | K23: =IFERROR(VLOOKUP(B23,'WIP - Paste Data'!B:E,4,FALSE),"") | P23: =IFERROR(VLOOKUP(B23,'JTD Paste Data'!A:B,2,FALSE),"0") -> 0 | Q23: =SUM(P23+L23) -> 0 | R23: =IFERROR(VLOOKUP(B23,'JTD Paste Data'!A:C,3,FALSE),"0") -> 1515.55 | S23: =SUM(R23+M23) -> 1515.55 | T23: =SUM(Q23-S23) -> -1515.55 | U23: =IFERROR(T23/Q23,0) -> 0
A24: NSC--StarTouch Short | B24: 21047 | C24: N/A | D24: =IFERROR(VLOOKUP(B24,'MTD Hours Paste Data'!A:C,3,FALSE),"") -> 9.94 | E24: =IFERROR(VLOOKUP(B24,'ACDOCA - Paste Data'!B:G,6,FALSE),0) -> 2750 | F24: =E24 +L24 -> 2750 | G24: =IFERROR(VLOOKUP(B24,'ACDOCA - Paste Data'!B:H,7,FALSE),0) -> 782.42 | H24: =G24+M24 -> 782.42 | I24: =F24-H24 -> 1967.58 | J24: =IFERROR(I24/F24,0) -> 0.71548364 | K24: =IFERROR(VLOOKUP(B24,'WIP - Paste Data'!B:E,4,FALSE),"") -> 2750 | P24: =IFERROR(VLOOKUP(B24,'JTD Paste Data'!A:B,2,FALSE),"0") -> 2750 | Q24: =SUM(P24+L24) -> 2750 | R24: =IFERROR(VLOOKUP(B24,'JTD Paste Data'!A:C,3,FALSE),"0") -> 782.42 | S24: =SUM(R24+M24) -> 782.42 | T24: =SUM(Q24-S24) -> 1967.58 | U24: =IFERROR(T24/Q24,0) -> 0.71548364
A25: VZ-Verizon ID Harvard | B25: 21187 | C25: 2136011 | D25: =IFERROR(VLOOKUP(B25,'MTD Hours Paste Data'!A:C,3,FALSE),"") -> 0 | E25: =IFERROR(VLOOKUP(B25,'ACDOCA - Paste Data'!B:G,6,FALSE),0) -> 0 | F25: =E25 +L25 -> 0 | G25: =IFERROR(VLOOKUP(B25,'ACDOCA - Paste Data'!B:H,7,FALSE),0) -> 0 | H25: =G25+M25 -> 0 | I25: =F25-H25 -> 0 | J25: =IFERROR(I25/F25,0) -> 0 | K25: =IFERROR(VLOOKUP(B25,'WIP - Paste Data'!B:E,4,FALSE),"") -> 13875.74 | P25: =IFERROR(VLOOKUP(B25,'JTD Paste Data'!A:B,2,FALSE),"0") -> 269677.42 | Q25: =SUM(P25+L25) -> 269677.42 | R25: =IFERROR(VLOOKUP(B25,'JTD Paste Data'!A:C,3,FALSE),"0") -> 249220.14 | S25: =SUM(R25+M25) -> 249220.14 | T25: =SUM(Q25-S25) -> 20457.28 | U25: =IFERROR(T25/Q25,0) -> 0.075858335
A26: =VLOOKUP(B26,'SAP Contracts'!A:J,10,FALSE) -> VZ-Verizon ID Careywood | B26: =VLOOKUP(C26,'Active North Sky Projects'!C:D,2,FALSE) -> 21648 | C26: 2136012 | D26: =IFERROR(VLOOKUP(B26,'MTD Hours Paste Data'!A:C,3,FALSE),"") -> 0 | E26: =IFERROR(VLOOKUP(B26,'ACDOCA - Paste Data'!B:G,6,FALSE),0) -> 0 | F26: =E26 +L26 -> 0 | G26: =IFERROR(VLOOKUP(B26,'ACDOCA - Paste Data'!B:H,7,FALSE),0) -> 3198.39 | H26: =G26+M26 -> 3198.39 | I26: =F26-H26 -> -3198.39 | J26: =IFERROR(I26/F26,0) -> 0 | K26: =IFERROR(VLOOKUP(B26,'WIP - Paste Data'!B:E,4,FALSE),"") -> 337431.37 | P26: =IFERROR(VLOOKUP(B26,'JTD Paste Data'!A:B,2,FALSE),"0") -> 337431.37 | Q26: =SUM(P26+L26) -> 337431.37 | R26: =IFERROR(VLOOKUP(B26,'JTD Paste Data'!A:C,3,FALSE),"0") -> 340197.03 | S26: =SUM(R26+M26) -> 340197.03 | T26: =SUM(Q26-S26) -> -2765.66 | U26: =IFERROR(T26/Q26,0) -> -0.0081962148
A27: =VLOOKUP(B27,'SAP Contracts'!A:J,10,FALSE) -> VZ-Verizon Idaho Market (Msa) | B27: =VLOOKUP(C27,'Active North Sky Projects'!C:D,2,FALSE) -> 21643 | C27: 2135002 | D27: =IFERROR(VLOOKUP(B27,'MTD Hours Paste Data'!A:C,3,FALSE),"") -> 55.35 | E27: =IFERROR(VLOOKUP(B27,'ACDOCA - Paste Data'!B:G,6,FALSE),0) -> 1 | F27: =E27 +L27 -> 1 | G27: =IFERROR(VLOOKUP(B27,'ACDOCA - Paste Data'!B:H,7,FALSE),0) -> 4894.27 | H27: =G27+M27 -> 4894.27 | I27: =F27-H27 -> -4893.27 | J27: =IFERROR(I27/F27,0) -> -4893.27 | K27: =IFERROR(VLOOKUP(B27,'WIP - Paste Data'!B:E,4,FALSE),"") -> 138947.03 | P27: =IFERROR(VLOOKUP(B27,'JTD Paste Data'!A:B,2,FALSE),"0") -> 1254903.4 | Q27: =SUM(P27+L27) -> 1254903.4 | R27: =IFERROR(VLOOKUP(B27,'JTD Paste Data'!A:C,3,FALSE),"0") -> 1179314.8 | S27: =SUM(R27+M27) -> 1179314.8 | T27: =SUM(Q27-S27) -> 75588.56 | U27: =IFERROR(T27/Q27,0) -> 0.060234566
A28: =VLOOKUP(B28,'SAP Contracts'!A:J,10,FALSE) -> VZ-Verizon Or Market (MSA) | B28: =VLOOKUP(C28,'Active North Sky Projects'!C:D,2,FALSE) -> 21145 | C28: 2384111 | D28: =IFERROR(VLOOKUP(B28,'MTD Hours Paste Data'!A:C,3,FALSE),"") -> 0 | E28: =IFERROR(VLOOKUP(B28,'ACDOCA - Paste Data'!B:G,6,FALSE),0) -> 0 | F28: =E28 +L28 -> 0 | G28: =IFERROR(VLOOKUP(B28,'ACDOCA - Paste Data'!B:H,7,FALSE),0) -> 0 | H28: =G28+M28 -> 0 | I28: =F28-H28 -> 0 | J28: =IFERROR(I28/F28,0) -> 0 | K28: =IFERROR(VLOOKUP(B28,'WIP - Paste Data'!B:E,4,FALSE),"") -> 77449.54 | P28: =IFERROR(VLOOKUP(B28,'JTD Paste Data'!A:B,2,FALSE),"0") -> 3748513.8 | Q28: =SUM(P28+L28) -> 3748513.8 | R28: =IFERROR(VLOOKUP(B28,'JTD Paste Data'!A:C,3,FALSE),"0") -> 3497940 | S28: =SUM(R28+M28) -> 3497940 | T28: =SUM(Q28-S28) -> 250573.83 | U28: =IFERROR(T28/Q28,0) -> 0.06684618
A29: =VLOOKUP(B29,'SAP Contracts'!A:J,10,FALSE) -> VZ-Verizon Or Mosser | B29: =VLOOKUP(C29,'Active North Sky Projects'!C:D,2,FALSE) -> 21579 | C29: 2384101 | D29: =IFERROR(VLOOKUP(B29,'MTD Hours Paste Data'!A:C,3,FALSE),"") | E29: =IFERROR(VLOOKUP(B29,'ACDOCA - Paste Data'!B:G,6,FALSE),0) -> 0 | F29: =E29 +L29 -> 0 | G29: =IFERROR(VLOOKUP(B29,'ACDOCA - Paste Data'!B:H,7,FALSE),0) -> 0 | H29: =G29+M29 -> 0 | I29: =F29-H29 -> 0 | J29: =IFERROR(I29/F29,0) -> 0 | K29: =IFERROR(VLOOKUP(B29,'WIP - Paste Data'!B:E,4,FALSE),"") -> 6225.64 | P29: =IFERROR(VLOOKUP(B29,'JTD Paste Data'!A:B,2,FALSE),"0") -> 85176.52 | Q29: =SUM(P29+L29) -> 85176.52 | R29: =IFERROR(VLOOKUP(B29,'JTD Paste Data'!A:C,3,FALSE),"0") -> 71641.24 | S29: =SUM(R29+M29) -> 71641.24 | T29: =SUM(Q29-S29) -> 13535.28 | U29: =IFERROR(T29/Q29,0) -> 0.15890858
A30: =VLOOKUP(B30,'SAP Contracts'!A:J,10,FALSE) -> VZ-Verizon OR Ruch | B30: =VLOOKUP(C30,'Active North Sky Projects'!C:D,2,FALSE) -> 21903 | C30: 2387000 | D30: =IFERROR(VLOOKUP(B30,'MTD Hours Paste Data'!A:C,3,FALSE),"") | E30: =IFERROR(VLOOKUP(B30,'ACDOCA - Paste Data'!B:G,6,FALSE),0) -> 2120 | F30: =E30 +L30 -> 2120 | G30: =IFERROR(VLOOKUP(B30,'ACDOCA - Paste Data'!B:H,7,FALSE),0) -> 1558.65 | H30: =G30+M30 -> 1558.65 | I30: =F30-H30 -> 561.35 | J30: =IFERROR(I30/F30,0) -> 0.26478774 | K30: =IFERROR(VLOOKUP(B30,'WIP - Paste Data'!B:E,4,FALSE),"") -> 13622.54 | P30: =IFERROR(VLOOKUP(B30,'JTD Paste Data'!A:B,2,FALSE),"0") -> 51720.16 | Q30: =SUM(P30+L30) -> 51720.16 | R30: =IFERROR(VLOOKUP(B30,'JTD Paste Data'!A:C,3,FALSE),"0") -> 45205.92 | S30: =SUM(R30+M30) -> 45205.92 | T30: =SUM(Q30-S30) -> 6514.24 | U30: =IFERROR(T30/Q30,0) -> 0.12595166
A31: =VLOOKUP(B31,'SAP Contracts'!A:J,10,FALSE) -> VZ-Verizon Spokane Market (MSA) | B31: =VLOOKUP(C31,'Active North Sky Projects'!C:D,2,FALSE) -> 21135 | C31: 2484111 | D31: =IFERROR(VLOOKUP(B31,'MTD Hours Paste Data'!A:C,3,FALSE),"") -> 0 | E31: =IFERROR(VLOOKUP(B31,'ACDOCA - Paste Data'!B:G,6,FALSE),0) -> 0 | F31: =E31 +L31 -> 0 | G31: =IFERROR(VLOOKUP(B31,'ACDOCA - Paste Data'!B:H,7,FALSE),0) -> 0 | H31: =G31+M31 -> 0 | I31: =F31-H31 -> 0 | J31: =IFERROR(I31/F31,0) -> 0 | K31: =IFERROR(VLOOKUP(B31,'WIP - Paste Data'!B:E,4,FALSE),"") -> 88717.35 | P31: =IFERROR(VLOOKUP(B31,'JTD Paste Data'!A:B,2,FALSE),"0") -> 775765.17 | Q31: =SUM(P31+L31) -> 775765.17 | R31: =IFERROR(VLOOKUP(B31,'JTD Paste Data'!A:C,3,FALSE),"0") -> 756555.52 | S31: =SUM(R31+M31) -> 756555.52 | T31: =SUM(Q31-S31) -> 19209.65 | U31: =IFERROR(T31/Q31,0) -> 0.024762197
A32: =VLOOKUP(B32,'SAP Contracts'!A:J,10,FALSE) -> VZ-Verizon Sw Wa Market (MSA) | B32: =VLOOKUP(C32,'Active North Sky Projects'!C:D,2,FALSE) -> 21196 | C32: 2484116 | D32: =IFERROR(VLOOKUP(B32,'MTD Hours Paste Data'!A:C,3,FALSE),"") -> 0 | E32: =IFERROR(VLOOKUP(B32,'ACDOCA - Paste Data'!B:G,6,FALSE),0) -> 1964.41 | F32: =E32 +L32 -> 1964.41 | G32: =IFERROR(VLOOKUP(B32,'ACDOCA - Paste Data'!B:H,7,FALSE),0) -> 2778.31 | H32: =G32+M32 -> 2778.31 | I32: =F32-H32 -> -813.9 | J32: =IFERROR(I32/F32,0) -> -0.41432288 | K32: =IFERROR(VLOOKUP(B32,'WIP - Paste Data'!B:E,4,FALSE),"") -> 1964.41 | P32: =IFERROR(VLOOKUP(B32,'JTD Paste Data'!A:B,2,FALSE),"0") -> 1249465.6 | Q32: =SUM(P32+L32) -> 1249465.6 | R32: =IFERROR(VLOOKUP(B32,'JTD Paste Data'!A:C,3,FALSE),"0") -> 1176895.2 | S32: =SUM(R32+M32) -> 1176895.2 | T32: =SUM(Q32-S32) -> 72570.43 | U32: =IFERROR(T32/Q32,0) -> 0.058081173
A33: =VLOOKUP(B33,'SAP Contracts'!A:J,10,FALSE) -> VZ-Verizon Wa North Colfax | B33: =VLOOKUP(C33,'Active North Sky Projects'!C:D,2,FALSE) -> 21242 | C33: 2485013 | D33: =IFERROR(VLOOKUP(B33,'MTD Hours Paste Data'!A:C,3,FALSE),"") | E33: =IFERROR(VLOOKUP(B33,'ACDOCA - Paste Data'!B:G,6,FALSE),0) -> 0 | F33: =E33 +L33 -> 0 | G33: =IFERROR(VLOOKUP(B33,'ACDOCA - Paste Data'!B:H,7,FALSE),0) -> 0 | H33: =G33+M33 -> 0 | I33: =F33-H33 -> 0 | J33: =IFERROR(I33/F33,0) -> 0 | K33: =IFERROR(VLOOKUP(B33,'WIP - Paste Data'!B:E,4,FALSE),"") -> 6497.5 | P33: =IFERROR(VLOOKUP(B33,'JTD Paste Data'!A:B,2,FALSE),"0") -> 230835.16 | Q33: =SUM(P33+L33) -> 230835.16 | R33: =IFERROR(VLOOKUP(B33,'JTD Paste Data'!A:C,3,FALSE),"0") -> 211644.11 | S33: =SUM(R33+M33) -> 211644.11 | T33: =SUM(Q33-S33) -> 19191.05 | U33: =IFERROR(T33/Q33,0) -> 0.083137465
A34: VZ- Verizon 2026 | B34: 22008 | C34: N/A | D34: =IFERROR(VLOOKUP(B34,'MTD Hours Paste Data'!A:C,3,FALSE),"") | E34: =IFERROR(VLOOKUP(B34,'ACDOCA - Paste Data'!B:G,6,FALSE),0) -> 86853.78 | F34: =E34 +L34 -> 86853.78 | G34: =IFERROR(VLOOKUP(B34,'ACDOCA - Paste Data'!B:H,7,FALSE),0) -> 61812.59 | H34: =G34+M34 -> 61812.59 | I34: =F34-H34 -> 25041.19 | J34: =IFERROR(I34/F34,0) -> 0.28831434 | K34: =IFERROR(VLOOKUP(B34,'WIP - Paste Data'!B:E,4,FALSE),"") -> 227167.44 | P34: =IFERROR(VLOOKUP(B34,'JTD Paste Data'!A:B,2,FALSE),"0") -> 227167.44 | Q34: =SUM(P34+L34) -> 227167.44 | R34: =IFERROR(VLOOKUP(B34,'JTD Paste Data'!A:C,3,FALSE),"0") -> 177646.56 | S34: =SUM(R34+M34) -> 177646.56 | T34: =SUM(Q34-S34) -> 49520.88 | U34: =IFERROR(T34/Q34,0) -> 0.21799286
A35: VZ - Timbers | B35: 22048 | C35: N/A | D35: =IFERROR(VLOOKUP(B35,'MTD Hours Paste Data'!A:C,3,FALSE),"") | E35: =IFERROR(VLOOKUP(B35,'ACDOCA - Paste Data'!B:G,6,FALSE),0) -> 0 | F35: =E35 +L35 -> 0 | G35: =IFERROR(VLOOKUP(B35,'ACDOCA - Paste Data'!B:H,7,FALSE),0) -> 0 | H35: =G35+M35 -> 0 | I35: =F35-H35 -> 0 | J35: =IFERROR(I35/F35,0) -> 0 | K35: =IFERROR(VLOOKUP(B35,'WIP - Paste Data'!B:E,4,FALSE),"") | P35: =IFERROR(VLOOKUP(B35,'JTD Paste Data'!A:B,2,FALSE),"0") -> 8540.16 | Q35: =SUM(P35+L35) -> 8540.16 | R35: =IFERROR(VLOOKUP(B35,'JTD Paste Data'!A:C,3,FALSE),"0") -> 1117.29 | S35: =SUM(R35+M35) -> 1117.29 | T35: =SUM(Q35-S35) -> 7422.87 | U35: =IFERROR(T35/Q35,0) -> 0.86917224
A36: =VLOOKUP(B36,'SAP Contracts'!A:J,10,FALSE) -> T-Mobile-Idaho Market 2024-2025 | B36: =VLOOKUP(C36,'Active North Sky Projects'!C:D,2,FALSE) -> 21161 | C36: 2135000 | D36: =IFERROR(VLOOKUP(B36,'MTD Hours Paste Data'!A:C,3,FALSE),"") | E36: =IFERROR(VLOOKUP(B36,'ACDOCA - Paste Data'!B:G,6,FALSE),0) -> 0 | F36: =E36 +L36 -> 0 | G36: =IFERROR(VLOOKUP(B36,'ACDOCA - Paste Data'!B:H,7,FALSE),0) -> 0 | H36: =G36+M36 -> 0 | I36: =F36-H36 -> 0 | J36: =IFERROR(I36/F36,0) -> 0 | K36: =IFERROR(VLOOKUP(B36,'WIP - Paste Data'!B:E,4,FALSE),"") | P36: =IFERROR(VLOOKUP(B36,'JTD Paste Data'!A:B,2,FALSE),"0") -> 0 | Q36: =SUM(P36+L36) -> 0 | R36: =IFERROR(VLOOKUP(B36,'JTD Paste Data'!A:C,3,FALSE),"0") -> 0 | S36: =SUM(R36+M36) -> 0 | T36: =SUM(Q36-S36) -> 0 | U36: =IFERROR(T36/Q36,0) -> 0
A37: Total Wireless Projects | B37: PCA | E37: =SUM(E5:E36) -> 294138.31 | F37: =SUM(F5:F36) -> 294138.31 | G37: =SUM(G5:G36) -> 270802.56 | H37: =SUM(H5:H36) -> 270802.56 | I37: =F37-H37 -> 23335.75 | J37: =IFERROR(I37/F37,0) -> 0.079335976 | K37: =SUM(K5:K36) -> 2060337.1 | L37: =SUM(L5:L36) -> 0 | M37: =SUM(M5:M36) -> 0 | O37: =SUM(O5:O36) -> 0 | P37: =SUM(P5:P36) -> 13174519 | Q37: =SUM(Q5:Q36) -> 13174519 | R37: =SUM(R5:R36) -> 12336460 | S37: =SUM(S5:S36) -> 12336460 | T37: =SUM(T5:T36) -> 838059.12 | U37: =IFERROR(T37/Q37,0) -> 0.063612124
A38: Div 2 - Structured Wiring PNW - Jason
A39: =VLOOKUP(B39,'SAP Contracts'!A:J,10,FALSE) -> Astound - OR Wave Broadband | B39: =VLOOKUP(C39,'Active North Sky Projects'!C:D,2,FALSE) -> 21586 | C39: 2385000 | D39: =IFERROR(VLOOKUP(B39,'MTD Hours Paste Data'!A:C,3,FALSE),"") -> 0 | E39: =IFERROR(VLOOKUP(B39,'ACDOCA - Paste Data'!B:G,6,FALSE),0) -> 0 | F39: =E39 +L39 -> 0 | G39: =IFERROR(VLOOKUP(B39,'ACDOCA - Paste Data'!B:H,7,FALSE),0) -> 0 | H39: =G39+M39 -> 0 | I39: =F39-H39 -> 0 | J39: =IFERROR(I39/F39,0) -> 0 | K39: =IFERROR(VLOOKUP(B39,'WIP - Paste Data'!B:E,4,FALSE),"") -> 11862.94 | P39: =IFERROR(VLOOKUP(B39,'JTD Paste Data'!A:B,2,FALSE),"0") -> 440215.08 | Q39: =SUM(P39+L39) -> 440215.08 | R39: =IFERROR(VLOOKUP(B39,'JTD Paste Data'!A:C,3,FALSE),"0") -> 335168.35 | S39: =SUM(R39+M39) -> 335168.35 | T39: =SUM(Q39-S39) -> 105046.73 | U39: =IFERROR(T39/Q39,0) -> 0.23862592
A40: =VLOOKUP(B40,'SAP Contracts'!A:J,10,FALSE) -> Astound - WA Wave Broadband | B40: =VLOOKUP(C40,'Active North Sky Projects'!C:D,2,FALSE) -> 21398 | C40: 2484117 | D40: =IFERROR(VLOOKUP(B40,'MTD Hours Paste Data'!A:C,3,FALSE),"") -> 76.46 | E40: =IFERROR(VLOOKUP(B40,'ACDOCA - Paste Data'!B:G,6,FALSE),0) -> 12000 | F40: =E40 +L40 -> 12000 | G40: =IFERROR(VLOOKUP(B40,'ACDOCA - Paste Data'!B:H,7,FALSE),0) -> 17256.38 | H40: =G40+M40 -> 17256.38 | I40: =F40-H40 -> -5256.38 | J40: =IFERROR(I40/F40,0) -> -0.43803167 | K40: =IFERROR(VLOOKUP(B40,'WIP - Paste Data'!B:E,4,FALSE),"") -> 159215.92 | P40: =IFERROR(VLOOKUP(B40,'JTD Paste Data'!A:B,2,FALSE),"0") -> 1858637.4 | Q40: =SUM(P40+L40) -> 1858637.4 | R40: =IFERROR(VLOOKUP(B40,'JTD Paste Data'!A:C,3,FALSE),"0") -> 1520921.8 | S40: =SUM(R40+M40) -> 1520921.8 | T40: =SUM(Q40-S40) -> 337715.67 | U40: =IFERROR(T40/Q40,0) -> 0.18170067
...

Sheet CX
A3: Job No | B3: Description | C3: MGR Report
A4: 00EQUIP | B4: 00-Shop Equipment | C4: =VLOOKUP(A4,MGR!A:A,2,FALSE) -> #N/A
A5: 00INDOH | B5: 00 - Indirect Cost | C5: =VLOOKUP(A5,MGR!A:A,2,FALSE) -> #N/A
A6: 1055129 | B6: ATT-Douglas City Bridge | C6: =VLOOKUP(A6,MGR!A:A,2,FALSE) -> #N/A
A7: 1055133 | B7: Siskiyou Tel-Mugginsville | C7: =VLOOKUP(A7,MGR!A:A,2,FALSE) -> #N/A
A8: 1055134 | B8: Siskiyou Tel-West Horse Creek | C8: =VLOOKUP(A8,MGR!A:A,2,FALSE) -> #N/A
A9: 1055196 | B9: Siskiyou Tel-Rattlesnake | C9: =VLOOKUP(A9,MGR!A:A,2,FALSE) -> #N/A
A10: 1055210 | B10: CAL-Ore 2024 | C10: =VLOOKUP(A10,MGR!A:A,2,FALSE) -> #N/A
A11: 1056117 | B11: Siskiyou Tel- OSP Routine Maintenance 2 | C11: =VLOOKUP(A11,MGR!A:A,2,FALSE) -> #N/A
A12: 1134140 | B12: Lumen-2022LE000008 Idaho | C12: =VLOOKUP(A12,MGR!A:A,2,FALSE) -> #N/A
A13: 1135184 | B13: Ziply - ID FTTP MSA (Rob) | C13: =VLOOKUP(A13,MGR!A:A,2,FALSE) -> #N/A
A14: 1135204 | B14: Avista - Poleline Substation | C14: =VLOOKUP(A14,MGR!A:A,2,FALSE) -> #N/A
A15: 1135248 | B15: Cogent-14428 Meyers Rd | C15: =VLOOKUP(A15,MGR!A:A,2,FALSE) -> #N/A
... A163: #VALUE! | B163: #VALUE! | C163: =VLOOKUP(A163,MGR!A:A,2,FALSE) -> #N/A
C164: =VLOOKUP(A164,MGR!A:A,2,FALSE) -> #N/A
C165: =VLOOKUP(A165,MGR!A:A,2,FALSE) -> #N/A
C166: =VLOOKUP(A166,MGR!A:A,2,FALSE) -> #N/A
C167: =VLOOKUP(A167,MGR!A:A,2,FALSE) -> #N/A
C168: =VLOOKUP(A168,MGR!A:A,2,FALSE) -> #N/A
C169: =VLOOKUP(A169,MGR!A:A,2,FALSE) -> #N/A
C170: =VLOOKUP(A170,MGR!A:A,2,FALSE) -> #N/A
C171: =VLOOKUP(A171,MGR!A:A,2,FALSE) -> #N/A
C172: =VLOOKUP(A172,MGR!A:A,2,FALSE) -> #N/A
C173: =VLOOKUP(A173,MGR!A:A,2,FALSE) -> #N/A
C174: =VLOOKUP(A174,MGR!A:A,2,FALSE) -> #N/A
C175: =VLOOKUP(A175,MGR!A:A,2,FALSE) -> #N/A
... C197: =VLOOKUP(A197,MGR!A:A,2,FALSE) -> #N/A

Sheet Legacy Lookup Table
D3: This Period | K3: Job - To -Date
A4: Job No | B4: Description | C4: Job | D4: Earned Revenue | E4: Acutal Cost | F4: Gross Profit | G4: GP % | H4: Billed | I4: WIP | J4: Contract Value | K4: JTD Earned Rev | L4: Actual Cost2 | M4: JTD Gross Profit | N4: JTD GP % | O4: CV
A5: =LEFT(C5,FIND(" ",C5)-1) -> #VALUE! | B5: =RIGHT(C5,LEN(C5)-FIND(" ",C5)) -> #VALUE! | C5: 000000 | D5: Projects, Indirect
A6: =LEFT(C6,FIND(" ",C6)-1) -> #VALUE! | B6: =RIGHT(C6,LEN(C6)-FIND(" ",C6)) -> #VALUE!
A7: =LEFT(C7,FIND(" ",C7)-1) -> #VALUE! | B7: =RIGHT(C7,LEN(C7)-FIND(" ",C7)) -> #VALUE! | C7: 0 | D7: 0
A8: =LEFT(C8,FIND(" ",C8)-1) -> #VALUE! | B8: =RIGHT(C8,LEN(C8)-FIND(" ",C8)) -> #VALUE!
A9: =LEFT(C9,FIND(" ",C9)-1) -> #VALUE! | B9: =RIGHT(C9,LEN(C9)-FIND(" ",C9)) -> #VALUE! | D9: 0
A10: =LEFT(C10,FIND(" ",C10)-1) -> 00INDOH | B10: =RIGHT(C10,LEN(C10)-FIND(" ",C10)) -> 00 - Indirect Cost | C10: 00INDOH 00 - Indirect Cost | D10: 10153.5 | E10: 777175.44 | F10: -767021.94 | G10: -7554.2615 | H10: 112638 | I10: 0 | J10: 0 | K10: 112638 | L10: 43187998 | M10: -43075360 | N10: -38242.298
A11: =LEFT(C11,FIND(" ",C11)-1) -> #VALUE! | B11: =RIGHT(C11,LEN(C11)-FIND(" ",C11)) -> #VALUE! | C11: 000000 | D11: Projects, Indirect | E11: 10153.5 | F11: -767021.94 | G11: 112638 | H11: 112638 | I11: -43075360 | J11: 777175.44 | K11: -7554.2615 | L11: 0 | M11: 43187998 | N11: -38242.298
A12: =LEFT(C12,FIND(" ",C12)-1) -> #VALUE! | B12: =RIGHT(C12,LEN(C12)-FIND(" ",C12)) -> #VALUE! | C12: 070771 | D12: Cox, Randy
A13: =LEFT(C13,FIND(" ",C13)-1) -> #VALUE! | B13: =RIGHT(C13,LEN(C13)-FIND(" ",C13)) -> #VALUE!
A14: =LEFT(C14,FIND(" ",C14)-1) -> #VALUE! | B14: =RIGHT(C14,LEN(C14)-FIND(" ",C14)) -> #VALUE! | C14: 0 | D14: 0
A15: =LEFT(C15,FIND(" ",C15)-1) -> #VALUE! | B15: =RIGHT(C15,LEN(C15)-FIND(" ",C15)) -> #VALUE!
A16: =LEFT(C16,FIND(" ",C16)-1) -> #VALUE! | B16: =RIGHT(C16,LEN(C16)-FIND(" ",C16)) -> #VALUE! | D16: 0
A17: =LEFT(C17,FIND(" ",C17)-1) -> 1056119 | B17: =RIGHT(C17,LEN(C17)-FIND(" ",C17)) -> SierraTel - Coarsegold Yosemite - Ph 4A | C17: 1056119 SierraTel - Coarsegold Yosemite - Ph 4A | D17: -36000 | E17: -24771.6 | F17: -11228.4 | G17: 0 | H17: 2912357.4 | I17: -36000 | J17: 0 | K17: 2876357.4 | L17: 2891407.4 | M17: -15050.06 | N17: -0.52323332
A18: =LEFT(C18,FIND(" ",C18)-1) -> #VALUE! | B18: =RIGHT(C18,LEN(C18)-FIND(" ",C18)) -> #VALUE!
A19: =LEFT(C19,FIND(" ",C19)-1) -> #VALUE! | B19: =RIGHT(C19,LEN(C19)-FIND(" ",C19)) -> #VALUE! | C19: 0 | D19: 0
A20: =LEFT(C20,FIND(" ",C20)-1) -> #VALUE! | B20: =RIGHT(C20,LEN(C20)-FIND(" ",C20)) -> #VALUE!
A21: =LEFT(C21,FIND(" ",C21)-1) -> #VALUE! | B21: =RIGHT(C21,LEN(C21)-FIND(" ",C21)) -> #VALUE! | D21: 0
A22: =LEFT(C22,FIND(" ",C22)-1) -> 1056136 | B22: =RIGHT(C22,LEN(C22)-FIND(" ",C22)) -> Frontier - Maint SSP Valley (2025-27) | C22: 1056136 Frontier - Maint SSP Valley (2025-27) | D22: 241329.62 | E22: 219177.3 | F22: 22152.32 | G22: 9.1792794 | H22: 1271043.3 | I22: 463995.06 | J22: 0 | K22: 1735038.4 | L22: 1460289.7 | M22: 274748.64 | N22: 15.835306
A23: =LEFT(C23,FIND(" ",C23)-1) -> #VALUE! | B23: =RIGHT(C23,LEN(C23)-FIND(" ",C23)) -> #VALUE!
A24: =LEFT(C24,FIND(" ",C24)-1) -> #VALUE! | B24: =RIGHT(C24,LEN(C24)-FIND(" ",C24)) -> #VALUE! | C24: 1998809 | D24: 1998809
A25: =LEFT(C25,FIND(" ",C25)-1) -> #VALUE! | B25: =RIGHT(C25,LEN(C25)-FIND(" ",C25)) -> #VALUE!
A26: =LEFT(C26,FIND(" ",C26)-1) -> #VALUE! | B26: =RIGHT(C26,LEN(C26)-FIND(" ",C26)) -> #VALUE! | D26: 0
A27: =LEFT(C27,FIND(" ",C27)-1) -> 1056155 | B27: =RIGHT(C27,LEN(C27)-FIND(" ",C27)) -> Ponderosa - Reconnect 3 - Build 1 | C27: 1056155 Ponderosa - Reconnect 3 - Build 1 | D27: 0 | E27: 1566.25 | F27: -1566.25 | G27: 0 | H27: 1199115.3 | I27: 0 | J27: 1998809 | K27: 1199115.3 | L27: 921004.71 | M27: 278110.59 | N27: 23.192982
A28: =LEFT(C28,FIND(" ",C28)-1) -> #VALUE! | B28: =RIGHT(C28,LEN(C28)-FIND(" ",C28)) -> #VALUE!
A29: =LEFT(C29,FIND(" ",C29)-1) -> #VALUE! | B29: =RIGHT(C29,LEN(C29)-FIND(" ",C29)) -> #VALUE! | C29: 9016.3 | D29: 9016.3
A30: =LEFT(C30,FIND(" ",C30)-1) -> #VALUE! | B30: =RIGHT(C30,LEN(C30)-FIND(" ",C30)) -> #VALUE!
A31: =LEFT(C31,FIND(" ",C31)-1) -> #VALUE! | B31: =RIGHT(C31,LEN(C31)-FIND(" ",C31)) -> #VALUE! | D31: 0
A32: =LEFT(C32,FIND(" ",C32)-1) -> 1056168 | B32: =RIGHT(C32,LEN(C32)-FIND(" ",C32)) -> Lumen - Bakersfield to Delano II - Splic | C32: 1056168 Lumen - Bakersfield to Delano II - Splic | D32: 0 | E32: 0 | F32: 0 | G32: 0 | H32: 12555.3 | I32: -9.094947e-13 | J32: 9016.3 | K32: 12555.3 | L32: 8022.58 | M32: 4532.72 | N32: 36.102045
A33: =LEFT(C33,FIND(" ",C33)-1) -> #VALUE! | B33: =RIGHT(C33,LEN(C33)-FIND(" ",C33)) -> #VALUE!
A34: =LEFT(C34,FIND(" ",C34)-1) -> #VALUE! | B34: =RIGHT(C34,LEN(C34)-FIND(" ",C34)) -> #VALUE! | C34: 71930 | D34: 71930
A35: =LEFT(C35,FIND(" ",C35)-1) -> #VALUE! | B35: =RIGHT(C35,LEN(C35)-FIND(" ",C35)) -> #VALUE!
A36: =LEFT(C36,FIND(" ",C36)-1) -> #VALUE! | B36: =RIGHT(C36,LEN(C36)-FIND(" ",C36)) -> #VALUE! | D36: 0
A37: =LEFT(C37,FIND(" ",C37)-1) -> 1056218 | B37: =RIGHT(C37,LEN(C37)-FIND(" ",C37)) -> BNCSI - Pine Flat to Dam Aerial Feed | C37: 1056218 BNCSI - Pine Flat to Dam Aerial Feed | D37: 0 | E37: 0 | F37: 0 | G37: 0 | H37: 79190 | I37: 0 | J37: 71930 | K37: 79190 | L37: 45732.67 | M37: 33457.33 | N37: 42.249438
A38: =LEFT(C38,FIND(" ",C38)-1) -> #VALUE! | B38: =RIGHT(C38,LEN(C38)-FIND(" ",C38)) -> #VALUE!
A39: =LEFT(C39,FIND(" ",C39)-1) -> #VALUE! | B39: =RIGHT(C39,LEN(C39)-FIND(" ",C39)) -> #VALUE! | C39: 431760 | D39: 431760
A40: =LEFT(C40,FIND(" ",C40)-1) -> #VALUE! | B40: =RIGHT(C40,LEN(C40)-FIND(" ",C40)) -> #VALUE!
A41: =LEFT(C41,FIND(" ",C41)-1) -> #VALUE! | B41: =RIGHT(C41,LEN(C41)-FIND(" ",C41)) -> #VALUE! | D41: 0
A42: =LEFT(C42,FIND(" ",C42)-1) -> 1056282 | B42: =RIGHT(C42,LEN(C42)-FIND(" ",C42)) -> ATT - A05AJGW - Coulterville | C42: 1056282 ATT - A05AJGW - Coulterville | D42: 174232.11 | E42: 257849.01 | F42: -83616.9 | G42: -47.99167 | H42: 0 | I42: 354095.06 | J42: 431760 | K42: 354095.06 | L42: 425639.22 | M42: -71544.16 | N42: -20.204789
...

Sheet ACDOCA - Paste Data
B2: Contract | C2: REVN | D2: COER | E2: D&A | F2: G&A | G2: Total Revenue | H2: Total Expense
A3: Paste into orange cell | C3: 0 | D3: 50002.06 | E3: 0 | F3: 346210.55 | G3: =SUM(Table1[[#This Row],[REVN]]*-1) -> 0 | H3: =Table1[[#This Row],[COER]] -> 50002.06
B4: 21041 | C4: 0 | D4: 211.9 | E4: 0 | F4: 0 | G4: =SUM(Table1[[#This Row],[REVN]]*-1) -> 0 | H4: =Table1[[#This Row],[COER]] -> 211.9
B5: 21044 | C5: -12204 | D5: 1293.27 | E5: 0 | F5: 0 | G5: =SUM(Table1[[#This Row],[REVN]]*-1) -> 12204 | H5: =Table1[[#This Row],[COER]] -> 1293.27
B6: 21047 | C6: -2750 | D6: 782.42 | E6: 0 | F6: 0 | G6: =SUM(Table1[[#This Row],[REVN]]*-1) -> 2750 | H6: =Table1[[#This Row],[COER]] -> 782.42
B7: 21048 | C7: 0 | D7: 0 | E7: 0 | F7: 0 | G7: =SUM(Table1[[#This Row],[REVN]]*-1) -> 0 | H7: =Table1[[#This Row],[COER]] -> 0
B8: 21053 | C8: 0 | D8: 0 | E8: 0 | F8: 0 | G8: =SUM(Table1[[#This Row],[REVN]]*-1) -> 0 | H8: =Table1[[#This Row],[COER]] -> 0
B9: 21056 | C9: 0 | D9: 0 | E9: 0 | F9: 0 | G9: =SUM(Table1[[#This Row],[REVN]]*-1) -> 0 | H9: =Table1[[#This Row],[COER]] -> 0
B10: 21057 | C10: 0 | D10: 0 | E10: 0 | F10: 0 | G10: =SUM(Table1[[#This Row],[REVN]]*-1) -> 0 | H10: =Table1[[#This Row],[COER]] -> 0
B11: 21060 | C11: 4652 | D11: -951.62 | E11: 0 | F11: 0 | G11: =SUM(Table1[[#This Row],[REVN]]*-1) -> -4652 | H11: =Table1[[#This Row],[COER]] -> -951.62
B12: 21061 | C12: 0 | D12: 0 | E12: 0 | F12: 0 | G12: =SUM(Table1[[#This Row],[REVN]]*-1) -> 0 | H12: =Table1[[#This Row],[COER]] -> 0
B13: 21064 | C13: 0 | D13: 0 | E13: 0 | F13: 0 | G13: =SUM(Table1[[#This Row],[REVN]]*-1) -> 0 | H13: =Table1[[#This Row],[COER]] -> 0
B14: 21065 | C14: -903 | D14: 959.37 | E14: 0 | F14: 0 | G14: =SUM(Table1[[#This Row],[REVN]]*-1) -> 903 | H14: =Table1[[#This Row],[COER]] -> 959.37
B15: 21067 | C15: -129240.96 | D15: 183712.32 | E15: 0 | F15: 0 | G15: =SUM(Table1[[#This Row],[REVN]]*-1) -> 129240.96 | H15: =Table1[[#This Row],[COER]] -> 183712.32
... B309: 22952 | C309: 0 | D309: 2787.77 | E309: 0 | F309: 0 | G309: =SUM(Table1[[#This Row],[REVN]]*-1) -> 0 | H309: =Table1[[#This Row],[COER]] -> 2787.77
C312: =SUM(Table1[REVN]) -> -11773491 | D312: =SUM(Table1[COER]) -> 10329748 | G312: =SUM(Table1[Total Revenue]) -> 11773491 | H312: =SUM(Table1[Total Expense]) -> 10329748

Sheet WIP - Paste Data
A1: Legacy Project # | B1: SAP Conract | C1: Project Description | D1: Profit Center | E1: Total | F1: 0-30 Days | G1: 31-60 Days | H1: 61-90 Days | I1: 91-120 Days | J1: 121-180 Days | K1: 181-360 Days | L1: 361-1080 Days | M1: 1081+ Days
B2: 21496 | C2: 1056203 | E2: 30785 | F2: 30785 | G2: 0 | H2: 0 | I2: 0 | J2: 0 | K2: 0 | L2: 0 | M2: 0
B3: 21044 | C3: 2036022 | E3: 12204 | F3: 12204 | G3: 0 | H3: 0 | I3: 0 | J3: 0 | K3: 0 | L3: 0 | M3: 0
B4: 21668 | C4: Adams County - Othello FTTH | E4: 2090212.4 | F4: 949164.25 | G4: 608166.36 | H4: 531816.76 | I4: 1065 | J4: 0 | K4: 0 | L4: 0 | M4: 0
B5: 21545 | C5: Alyrica - Webfoot | D5: PC8 - Washington (Kotulan) | E5: 486893.12 | F5: 0 | G5: 10551.28 | H5: 35105.7 | I5: 0 | J5: 0.34 | K5: 441235.8 | L5: 0 | M5: 0
B6: 21484 | C6: Arcadian - Redwood Segment 5-1 | E6: 2798213 | F6: 2777563 | G6: 20650 | H6: 0 | I6: 0 | J6: 0 | K6: 0 | L6: 0 | M6: 0
B7: 21655 | C7: Astound - Clallam County PWB Phase | D7: PC8 - Washington (Kotulan) | E7: 179735.34 | F7: 0 | G7: 8112 | H7: 34872.95 | I7: 81533.54 | J7: 55216.85 | K7: 0 | L7: 0 | M7: 0
B8: 21654 | C8: Astound - Clallam County WSBO Phase | D8: PC8 - Washington (Kotulan) | E8: 1675861.2 | F8: 705710.68 | G8: 737773.61 | H8: 232376.96 | I8: 0 | J8: 0 | K8: 0 | L8: 0 | M8: 0
B9: 21586 | C9: Astound - OR Wave Broadband | D9: PCA - Wireless (Shaffer) | E9: 11862.94 | F9: 0 | G9: 182.02 | H9: 7100 | I9: 0 | J9: 885.48 | K9: 3695.44 | L9: 0 | M9: 0
B10: 21387 | C10: Astound - WA- Oak Harbor | D10: PCA - Wireless (Shaffer) | E10: 8400 | F10: 0 | G10: 0 | H10: 0 | I10: 0 | J10: 0 | K10: 8400 | L10: 0 | M10: 0
B11: 21398 | C11: Astound - WA Wave Broadband | D11: PCA - Wireless (Shaffer) | E11: 159215.92 | F11: 22000 | G11: 28500 | H11: 21500 | I11: 15488.35 | J11: 31000 | K11: 40727.57 | L11: 0 | M11: 0
B12: 21565 | C12: AT&T - CDA Bridge Cable Pulling | E12: 64886 | F12: 0 | G12: 0 | H12: 64886 | I12: 0 | J12: 0 | K12: 0 | L12: 0 | M12: 0
B13: 21071 | C13: ATT - A02QY7S - Reno NV | D13: PC12 - CA Bay Area (Mullins) | E13: 502068.99 | F13: 49395.95 | G13: 64546.75 | H13: 211577.76 | I13: 23592.74 | J13: 138582.33 | K13: 14373.46 | L13: 0 | M13: 0
B14: 21077 | C14: ATT - A02PJDR - Kings Row | D14: PC12 - CA Bay Area (Mullins) | E14: 665309 | F14: 346660.59 | G14: 259798.73 | H14: 38179.07 | I14: 0 | J14: 20670.61 | K14: 0 | L14: 0 | M14: 0
B15: 21552 | C15: ATT - A051KQ2 - Carson City NV | D15: PC12 - CA Bay Area (Mullins) | E15: 344007.76 | F15: 0 | G15: 11938.15 | H15: 77199.81 | I15: 95150.6 | J15: 159719.2 | K15: 0 | L15: 0 | M15: 0
B16: 21283 | C16: ATT - A051W9F - 2101 Kala Bagai Way | E16: 6838.89 | F16: 0 | G16: 0 | H16: 0 | I16: 6838.89 | J16: 0 | K16: 0 | L16: 0 | M16: 0
B17: 21061 | C17: ATT - A0558LC - Sparks NV | D17: PC12 - CA Bay Area (Mullins) | E17: 568646.43 | F17: 0 | G17: 146508.23 | H17: 20824.91 | I17: 164625.66 | J17: 79403.83 | K17: 157283.8 | L17: 0 | M17: 0
B18: 21269 | C18: ATT - A055QP3 - Various | D18: PC12 - CA Bay Area (Mullins) | E18: 274166 | F18: 0 | G18: 0 | H18: 0 | I18: 71315 | J18: 28035 | K18: 174816 | L18: 0 | M18: 0
B19: 21878 | C19: ATT - A057WYA - San Rafael | E19: 484502 | F19: 92400 | G19: 315052 | H19: 77050 | I19: 0 | J19: 0 | K19: 0 | L19: 0 | M19: 0
B20: 22017 | C20: ATT - A0580A6 - Tehachapi | E20: 190304.42 | F20: 93149.07 | G20: 97155.35 | H20: 0 | I20: 0 | J20: 0 | K20: 0 | L20: 0 | M20: 0
B21: 21850 | C21: ATT - A058D26 - Greeley Hill | E21: 1085586.6 | F21: 49491.2 | G21: 0 | H21: 957080.77 | I21: 79014.58 | J21: 0 | K21: 0 | L21: 0 | M21: 0
B22: 21509 | C22: ATT - A058EV8 - Martinez | D22: PC12 - CA Bay Area (Mullins) | E22: 169757.96 | F22: 0 | G22: 0 | H22: 58792.7 | I22: 0 | J22: 110965.26 | K22: 0 | L22: 0 | M22: 0
B23: 21041 | C23: ATT - A058FR3 - 2 Paseo Linares | E23: 125373.1 | F23: 0 | G23: 82613.3 | H23: 0 | I23: 0 | J23: 0 | K23: 42759.8 | L23: 0 | M23: 0
B24: 21533 | C24: ATT - A058FR3 - Moraga | D24: PC12 - CA Bay Area (Mullins) | E24: 264289 | F24: 0 | G24: 91200 | H24: 23550 | I24: 0 | J24: 0 | K24: 149539 | L24: 0 | M24: 0
B25: 22077 | C25: ATT - A058LPX - Salinas | E25: 65297.85 | F25: 35148.46 | G25: 30149.39 | H25: 0 | I25: 0 | J25: 0 | K25: 0 | L25: 0 | M25: 0
B26: 21079 | C26: ATT - A058N3T - Moraga Dig Ups | D26: PC12 - CA Bay Area (Mullins) | E26: 20988 | F26: 0 | G26: 0 | H26: 0 | I26: 0 | J26: 0 | K26: 20988 | L26: 0 | M26: 0
B27: 21074 | C27: ATT - A058N3W - Harvard Circle | D27: PC12 - CA Bay Area (Mullins) | E27: 112064 | F27: 0 | G27: 0 | H27: 0 | I27: 69210 | J27: 0 | K27: 42854 | L27: 0 | M27: 0
B28: 21889 | C28: ATT - A058NZT - Reno NV | E28: 37101.75 | F28: 0 | G28: 37101.75 | H28: 0 | I28: 0 | J28: 0 | K28: 0 | L28: 0 | M28: 0
B29: 21893 | C29: ATT - A058YLP FTTH - Ceres | E29: 522950.61 | F29: 0 | G29: 8552 | H29: 290935.46 | I29: 223463.15 | J29: 0 | K29: 0 | L29: 0 | M29: 0
B30: 22016 | C30: ATT - A059EQC - Alameda | E30: 102109.22 | F30: 22066.5 | G30: 80042.72 | H30: 0 | I30: 0 | J30: 0 | K30: 0 | L30: 0 | M30: 0
B31: 21502 | C31: ATT - A059FVL - Alameda Rod and Rope | D31: PC12 - CA Bay Area (Mullins) | E31: 13334.1 | F31: 0 | G31: 0 | H31: 0 | I31: 0 | J31: 13334.1 | K31: 0 | L31: 0 | M31: 0
B32: 22076 | C32: ATT - A05AVJF - Stead | E32: 206709.24 | F32: 206709.24 | G32: 0 | H32: 0 | I32: 0 | J32: 0 | K32: 0 | L32: 0 | M32: 0
B33: 21946 | C33: ATT - A05BEYM - Fernley | E33: 78444.56 | F33: 78444.56 | G33: 0 | H33: 0 | I33: 0 | J33: 0 | K33: 0 | L33: 0 | M33: 0
B34: 21945 | C34: ATT - A05CD07 FTTH - Los Banos | E34: 708723.39 | F34: 26997.6 | G34: 570378.86 | H34: 111346.93 | I34: 0 | J34: 0 | K34: 0 | L34: 0 | M34: 0
B35: 21953 | C35: ATT - Blossom Hill Rd - HH Placement | E35: 21817.5 | F35: 18175 | G35: 3642.5 | H35: 0 | I35: 0 | J35: 0 | K35: 0 | L35: 0 | M35: 0
B36: 21527 | C36: ATT - BSW - Bay Area | E36: 41849.61 | F36: 23194.42 | G36: 18655.19 | H36: 0 | I36: 0 | J36: 0 | K36: 0 | L36: 0 | M36: 0
B37: 21265 | C37: ATT - BSW - Northern | E37: 4864.07 | F37: 4864.07 | G37: 0 | H37: 0 | I37: 0 | J37: 0 | K37: 0 | L37: 0 | M37: 0
B38: 21486 | C38: ATT - Dig MSA - Bay Area | D38: PC12 - CA Bay Area (Mullins) | E38: 59414.71 | F38: 44171.25 | G38: 13747.39 | H38: 1047.2 | I38: 448.87 | J38: 0 | K38: 0 | L38: 0 | M38: 0
B39: 21518 | C39: ATT - Dig MSA - Northern Areas | D39: PC12 - CA Bay Area (Mullins) | E39: 12021.9 | F39: 8276.24 | G39: 2760.16 | H39: 985.5 | I39: 0 | J39: 0 | K39: 0 | L39: 0 | M39: 0
B40: 22075 | C40: ATT - Joint Pole Bundle - Carson City | E40: 15386.7 | F40: 15386.7 | G40: 0 | H40: 0 | I40: 0 | J40: 0 | K40: 0 | L40: 0 | M40: 0
...

Sheet JTD Paste Data
A1: Contract | B1: JTD Revenue | C1: JTD Cost
A2: 21041 | B2: 125373.1 | C2: 84107.62
A3: 21044 | B3: 12204 | C3: 1293.27
A4: 21047 | B4: 2750 | C4: 782.42
A5: 21048 | B5: 0 | C5: 774.46
A6: 21053 | B6: 6500 | C6: 4309.11
A7: 21056 | B7: 33205.15 | C7: 25679.26
A8: 21057 | B8: 48099.55 | C8: 44805.26
A9: 21060 | B9: 37381 | C9: 31694.84
A10: 21061 | B10: 568646.43 | C10: 648982.12
A11: 21064 | B11: 4822163.1 | C11: 4171829.9
A12: 21065 | B12: 157023.23 | C12: 128331.51
A13: 21067 | B13: 5359735.1 | C13: 5568534.4
... A307: 22952 | B307: 0 | C307: 2787.77

Sheet MTD Hours Paste Data
A1: Contract | B1: MTD Revenue Amt | C1: MTD Hours | D1: MTD PROD | E1: MTD Direct Labor Cost | F1: MTD Direct Labor Cost Per Hour | G1: MTD Cost/Revenue Ratio | H1: QTD Revenue Amt | I1: QTD Hours | J1: QTD PROD | K1: QTD Direct Labor Cost | L1: QTD Direct Labor Cost Per Hour | M1: QTD Cost/Revenue Ratio | N1: YTD Revenue Amt | O1: YTD Hours | P1: YTD PROD | Q1: YTD Direct Labor Cost | R1: YTD Direct Labor Cost Per Hour | S1: YTD Cost/Revenue Ratio
A2: 20016 | B2: 25634 | C2: 84.11 | D2: 304.76756628224945 | E2: 8615.08 | F2: 102.42634645107597 | G2: 0.33608020597643756 | H2: 54188 | I2: 269.75 | J2: 200.8822984244671 | K2: 24051.24 | L2: 89.161223 | M2: 0.44384808444674095 | N2: 55368.5 | O2: 400.22 | P2: 138.34516016191094 | Q2: 26590.12 | R2: 66.438759 | S2: 0.48023912513432726
A3: 20017 | B3: 0 | C3: 0 | D3: 0 | E3: 0 | F3: 0 | G3: 0 | H3: 0 | I3: 0 | J3: 0 | K3: 0 | L3: 0 | M3: 0 | N3: -321277.47 | O3: 0 | P3: 0 | Q3: 0 | R3: 0 | S3: 0
A4: 20021 | B4: 0 | C4: 0 | D4: 0 | E4: 0 | F4: 0 | G4: 0 | H4: 0 | I4: 0 | J4: 0 | K4: 0 | L4: 0 | M4: 0 | N4: -116936.26 | O4: 193.78 | P4: -603.44855 | Q4: 9148.62 | R4: 47.21137372277841 | S4: -0.078235955
A5: 20025 | B5: 33464.96 | C5: 601.88 | D5: 55.60071775104672 | E5: 21498.52 | F5: 35.71894729846481 | G5: 0.6424188165771003 | H5: 110295.34 | I5: 1347.18 | J5: 81.87127184192164 | K5: 48768.53 | L5: 36.20045576686115 | M5: 0.4421631049870285 | N5: 138533.77 | O5: 1564.77 | P5: 88.53299206912197 | Q5: 56541.3 | R5: 36.13393661688299 | S5: 0.4081409175538932
A6: 20040 | B6: 9821.88 | C6: 19.76 | D6: 497.0587044534413 | E6: 538.71 | F6: 27.26265182186235 | G6: 0.054847951715964766 | H6: 12798.21 | I6: 165.66 | J6: 77.25588554871423 | K6: 5249.55 | L6: 31.68869974646867 | M6: 0.4101784546432665 | N6: 38893.29 | O6: 585.73 | P6: 66.40139654789749 | Q6: 18639.26 | R6: 31.82227306096666 | S6: 0.4792410207519086
A7: 20042 | B7: 0 | C7: 0 | D7: 0 | E7: 0 | F7: 0 | G7: 0 | H7: 0 | I7: 0 | J7: 0 | K7: 0 | L7: 0 | M7: 0 | N7: -766.95 | O7: 0 | P7: 0 | Q7: 0 | R7: 0 | S7: 0
A8: 20045 | B8: 0 | C8: 0 | D8: 0 | E8: 0 | F8: 0 | G8: 0 | H8: 0 | I8: 0 | J8: 0 | K8: 0 | L8: 0 | M8: 0 | N8: -97777.93 | O8: 38.58 | P8: -2534.4202 | Q8: 6543.16 | R8: 169.59979263867288 | S8: -0.066918578
A9: 20047 | B9: 0 | C9: 0 | D9: 0 | E9: 0 | F9: 0 | G9: 0 | H9: 0 | I9: 0 | J9: 0 | K9: 0 | L9: 0 | M9: 0 | N9: 3159.33 | O9: 0 | P9: 0 | Q9: 0 | R9: 0 | S9: 0
A10: 20049 | B10: 0 | C10: 80 | D10: 0 | E10: 4796.06 | F10: 59.95075 | G10: 0 | H10: 28658 | I10: 124.99 | J10: 229.28234 | K10: 4796.06 | L10: 38.37154972397792 | M10: 0.16735501430665084 | N10: 53261 | O10: 261.73 | P10: 203.4959691284912 | Q10: -5755.18 | R10: -21.988996 | S10: -0.10805618
A11: 20053 | B11: 437.57 | C11: 29.17 | D11: 15.000685635927322 | E11: 871.78 | F11: 29.88618443606445 | G11: 1.9923212286034235 | H11: 2207.1 | I11: 55.86 | J11: 39.51127819548872 | K11: 1707.24 | L11: 30.56283566058002 | M11: 0.7735218159575914 | N11: 6618.3 | O11: 189.46 | P11: 34.93244 | Q11: 5753.32 | R11: 30.36693761216088 | S11: 0.8693048063702159
A12: 20055 | B12: 0 | C12: 0 | D12: 0 | E12: 0 | F12: 0 | G12: 0 | H12: 0 | I12: 0 | J12: 0 | K12: 0 | L12: 0 | M12: 0 | N12: -863.17 | O12: 0 | P12: 0 | Q12: 0 | R12: 0 | S12: 0
A13: 20059 | B13: 0 | C13: 0 | D13: 0 | E13: 0 | F13: 0 | G13: 0 | H13: 0 | I13: 0 | J13: 0 | K13: 0 | L13: 0 | M13: 0 | N13: -1116.95 | O13: 0 | P13: 0 | Q13: 0 | R13: 0 | S13: 0
A14: 20060 | B14: 0 | C14: 0 | D14: 0 | E14: 0 | F14: 0 | G14: 0 | H14: 0 | I14: 0 | J14: 0 | K14: 0 | L14: 0 | M14: 0 | N14: -12848.08 | O14: 0 | P14: 0 | Q14: 0 | R14: 0 | S14: 0
A15: 20064 | B15: 0 | C15: 0 | D15: 0 | E15: 0 | F15: 0 | G15: 0 | H15: 0 | I15: 0 | J15: 0 | K15: 0 | L15: 0 | M15: 0 | N15: -8012.89 | O15: 0 | P15: 0 | Q15: 0 | R15: 0 | S15: 0
A16: 20069 | B16: 181772.02 | C16: 1857.58 | D16: 97.85420816330925 | E16: 58855.76 | F16: 31.684105126024182 | G16: 0.32378888676045964 | H16: 675919.19 | I16: 4651.88 | J16: 145.30022055599028 | K16: 150399.4 | L16: 32.33088557744396 | M16: 0.22251091879785215 | N16: 691401.37 | O16: 5055.61 | P16: 136.75923775765932 | Q16: 166642.4 | R16: 32.96187799296227 | S16: 0.24102121753099795
A17: 20073 | B17: 0 | C17: 0 | D17: 0 | E17: 0 | F17: 0 | G17: 0 | H17: 0 | I17: 0 | J17: 0 | K17: 0 | L17: 0 | M17: 0 | N17: -4384.76 | O17: 0 | P17: 0 | Q17: 0 | R17: 0 | S17: 0
A18: 20077 | B18: 0 | C18: 0 | D18: 0 | E18: 0 | F18: 0 | G18: 0 | H18: 0 | I18: 0 | J18: 0 | K18: 0 | L18: 0 | M18: 0 | N18: -237579.33 | O18: 0 | P18: 0 | Q18: 0 | R18: 0 | S18: 0
A19: 20080 | B19: 0 | C19: 0 | D19: 0 | E19: 0 | F19: 0 | G19: 0 | H19: 0 | I19: 0 | J19: 0 | K19: 0 | L19: 0 | M19: 0 | N19: -100362.2 | O19: 0 | P19: 0 | Q19: 0 | R19: 0 | S19: 0
A20: 20081 | B20: 11042.05 | C20: 220.52 | D20: 50.07278251405768 | E20: 6618.53 | F20: 30.013286776709595 | G20: 0.5993932286124406 | H20: 11042.05 | I20: 220.52 | J20: 50.07278251405768 | K20: 6618.53 | L20: 30.013286776709595 | M20: 0.5993932286124406 | N20: 11042.05 | O20: 220.52 | P20: 50.07278251405768 | Q20: 6618.53 | R20: 30.013286776709595 | S20: 0.5993932286124406
A21: 20082 | B21: 9839.7 | C21: 70.61 | D21: 139.35278289194164 | E21: 2283.28 | F21: 32.336496246990514 | G21: 0.23204772503226725 | H21: 9839.7 | I21: 18.54 | J21: 530.7281553398059 | K21: 4281.35 | L21: 230.92502696871628 | M21: 0.43510981025844286 | N21: 24552.6 | O21: 4867.37 | P21: 5.044325785793971 | Q21: 113532.86 | R21: 23.325298878038858 | S21: 4.624066697620618
A22: 20083 | B22: 0 | C22: 0 | D22: 0 | E22: 0 | F22: 0 | G22: 0 | H22: 0 | I22: 0 | J22: 0 | K22: 0 | L22: 0 | M22: 0 | N22: -134732.62 | O22: 0 | P22: 0 | Q22: 0 | R22: 0 | S22: 0
A23: 20086 | B23: 4023.32 | C23: 143.72 | D23: 27.994155301976065 | E23: 4316.59 | F23: 30.034720289451712 | G23: 1.0728925365121342 | H23: 9806.3 | I23: 318.47 | J23: 30.79191132602757 | K23: 9081.76 | L23: 28.51684617075392 | M23: 0.92611484 | N23: 57423.41 | O23: 862.26 | P23: 66.59639783823904 | Q23: 27842.88 | R23: 32.290585206318276 | S23: 0.4848698466357188
A24: 20087 | B24: 0 | C24: 0 | D24: 0 | E24: 0 | F24: 0 | G24: 0 | H24: 3555.68 | I24: 0 | J24: 0 | K24: 0 | L24: 0 | M24: 0 | N24: 44454.45 | O24: 701.48 | P24: 63.37236984661003 | Q24: 10902.2 | R24: 15.541711809317443 | S24: 0.24524428937935347
A25: 20088 | B25: 0 | C25: 16.62 | D25: 0 | E25: 478.32 | F25: 28.779783393501805 | G25: 0 | H25: 45 | I25: 36.12 | J25: 1.2458471760797343 | K25: 1039.53 | L25: 28.779900332225914 | M25: 23.100666666666665 | N25: 960 | O25: 117.76 | P25: 8.152173913043478 | Q25: 3619.23 | R25: 30.733950407608695 | S25: 3.7700313
A26: 20091 | B26: -2444.75 | C26: 0 | D26: 0 | E26: 0 | F26: 0 | G26: 0 | H26: -2444.75 | I26: 0 | J26: 0 | K26: 0 | L26: 0 | M26: 0 | N26: -3994.75 | O26: 0 | P26: 0 | Q26: 0 | R26: 0 | S26: 0
A27: 20092 | B27: 0 | C27: 0 | D27: 0 | E27: 0 | F27: 0 | G27: 0 | H27: 0 | I27: 0 | J27: 0 | K27: 0 | L27: 0 | M27: 0 | N27: -21167.8 | O27: 0 | P27: 0 | Q27: 0 | R27: 0 | S27: 0
A28: 20097 | B28: 0 | C28: 0 | D28: 0 | E28: 0 | F28: 0 | G28: 0 | H28: 0 | I28: 0 | J28: 0 | K28: 0 | L28: 0 | M28: 0 | N28: -119536.26 | O28: 112.52 | P28: -1062.3557 | Q28: 4040.88 | R28: 35.912548880199076 | S28: -0.033804638
A29: 20100 | B29: 94.38 | C29: 21.41 | D29: 4.408220457730033 | E29: 541.71 | F29: 25.301728164409155 | G29: 5.739669421487603 | H29: 7678.28 | I29: 158.9 | J29: 48.32146 | K29: 4421.07 | L29: 27.822970421648836 | M29: 0.5757891090192074 | N29: 20708.17 | O29: 409.41 | P29: 50.580518306831785 | Q29: 12553.23 | R29: 30.66175716274639 | S29: 0.6061969744308647
A30: 20101 | B30: 0 | C30: 0 | D30: 0 | E30: 0 | F30: 0 | G30: 0 | H30: 0 | I30: 0 | J30: 0 | K30: 0 | L30: 0 | M30: 0 | N30: -65552.95 | O30: 0 | P30: 0 | Q30: 0 | R30: 0 | S30: 0
A31: 20106 | B31: 0 | C31: 0 | D31: 0 | E31: 0 | F31: 0 | G31: 0 | H31: 303 | I31: 8.94 | J31: 33.89261744966443 | K31: 494.26 | L31: 55.28635346756152 | M31: 1.6312211221122113 | N31: 26201.08 | O31: 112.54 | P31: 232.81570996978851 | Q31: 7260.49 | R31: 64.51475031100053 | S31: 0.2771065162199421
A32: 20109 | B32: 0 | C32: 0 | D32: 0 | E32: 0 | F32: 0 | G32: 0 | H32: 0 | I32: 0 | J32: 0 | K32: 0 | L32: 0 | M32: 0 | N32: -18200.7 | O32: 15.28 | P32: -1191.1453 | Q32: 885.54 | R32: 57.954188481675395 | S32: -0.048654173
A33: 20111 | B33: 0 | C33: 0 | D33: 0 | E33: 0 | F33: 0 | G33: 0 | H33: 0 | I33: 0 | J33: 0 | K33: 0 | L33: 0 | M33: 0 | N33: -96954.05 | O33: 14.65 | P33: -6618.0239 | Q33: 1868.02 | R33: 127.5098976109215 | S33: -0.019267065
A34: 20113 | B34: 0 | C34: 0 | D34: 0 | E34: 0 | F34: 0 | G34: 0 | H34: -19218.78 | I34: 0 | J34: 0 | K34: 0 | L34: 0 | M34: 0 | N34: -19218.78 | O34: 0 | P34: 0 | Q34: 0 | R34: 0 | S34: 0
A35: 20115 | B35: 0 | C35: 0 | D35: 0 | E35: 0 | F35: 0 | G35: 0 | H35: 0 | I35: 0 | J35: 0 | K35: 0 | L35: 0 | M35: 0 | N35: -7790.21 | O35: 0 | P35: 0 | Q35: 0 | R35: 0 | S35: 0
A36: 20116 | B36: 0 | C36: 0 | D36: 0 | E36: 0 | F36: 0 | G36: 0 | H36: 0 | I36: 0 | J36: 0 | K36: 0 | L36: 0 | M36: 0 | N36: 3668.4 | O36: 71.87 | P36: 51.04215945457075 | Q36: 1996.06 | R36: 27.773201614025325 | S36: 0.5441227783229746
A37: 20120 | B37: 0 | C37: 0 | D37: 0 | E37: 0 | F37: 0 | G37: 0 | H37: 0 | I37: 0 | J37: 0 | K37: 0 | L37: 0 | M37: 0 | N37: -14621.25 | O37: 92.63 | P37: -157.84573 | Q37: 2640.1 | R37: 28.501565367591493 | S37: -0.18056596
A38: 20121 | B38: 7398 | C38: 22.71 | D38: 325.75957727873185 | E38: 785.55 | F38: 34.59048877146631 | G38: 0.10618410381184104 | H38: 7398 | I38: 22.71 | J38: 325.75957727873185 | K38: 785.55 | L38: 34.59048877146631 | M38: 0.10618410381184104 | N38: 7398 | O38: 22.71 | P38: 325.75957727873185 | Q38: 785.55 | R38: 34.59048877146631 | S38: 0.10618410381184104
A39: 20124 | B39: 0 | C39: 0 | D39: 0 | E39: 0 | F39: 0 | G39: 0 | H39: -39.11 | I39: 0 | J39: 0 | K39: 0 | L39: 0 | M39: 0 | N39: 0 | O39: 0 | P39: 0 | Q39: 0 | R39: 0 | S39: 0
A40: 20126 | B40: 0 | C40: 0 | D40: 0 | E40: 0 | F40: 0 | G40: 0 | H40: 0 | I40: 0 | J40: 0 | K40: 0 | L40: 0 | M40: 0 | N40: -134581.36 | O40: 7.55 | P40: -17825.346 | Q40: 259.08 | R40: 34.31523178807947 | S40: -0.0019250809
...

Sheet Sheet3
A2: Printed: 2/28/2026 2:52:30PM
F4: Unbilled Aging
A7: Customer Code: ALL
B8: Job Number: All
B10: Contract Code: All
B11: Cut Off Date: 02/28/2026
B13: Record Type: R
B14: Exclude Drafts: No
A15: UserID: 4395
A22: Cut Off Date: | B22: 02/28/2026 | C22: Total | D22: 0-30 Days | E22: 31-60 Days | F22: 61-90 Days | G22: 91-120 Days | H22: 121-180 Days | I22: 181-360 Days | J22: 361-1080 Days | K22: 1081+ Days
A24: Project Manager: Birdsall, Ron
A26: 1056143 | B26: Frontier - Maint SSP South Bay (2025-27) | C26: 284867.69 | D26: 98451.385 | E26: 52707.71 | F26: 25804.25 | G26: 52289.698 | H26: 41131.99 | I26: 14482.66 | J26: 0 | K26: 0
A28: 1056275 | B28: ATT - A058K7T - Salinas | C28: 109714.58 | D28: 7643.7 | E28: 102070.88 | F28: 0 | G28: 0 | H28: 0 | I28: 0 | J28: 0 | K28: 0
A30: 1252077 | B30: Frontier - FTTH Morgan Hill | C30: 223093.6 | D30: 222613.6 | E30: 480 | F30: 0 | G30: 0 | H30: 0 | I30: 0 | J30: 0 | K30: 0
A32: 1252082 | B32: Frontier - FTTH - Kenwood | C32: 611690.33 | D32: 438069.54 | E32: 120116.35 | F32: 52836.9 | G32: 667.54 | H32: 0 | I32: 0 | J32: 0 | K32: 0
C35: 1229366.2 | D35: 766778.22 | E35: 275374.94 | F35: 78641.15 | G35: 52957.238 | H35: 41131.99 | I35: 14482.66 | J35: 0 | K35: 0
A38: Project Manager: Bochsler, Dustin
A40: 1385258 | B40: Clear Creek-2024 OSP Phase III | C40: 39573.25 | D40: 18045.48 | E40: 20267.77 | F40: 1260 | G40: 0 | H40: 0 | I40: 0 | J40: 0 | K40: 0
A42: 1386138 | B42: Clear Creek - OSP Phase 3-1 | C42: 27372.44 | D42: 27266.72 | E42: 105.72 | F42: 0 | G42: 0 | H42: 0 | I42: 0 | J42: 0 | K42: 0
C45: 66945.69 | D45: 45312.2 | E45: 20373.49 | F45: 1260 | G45: 0 | H45: 0 | I45: 0 | J45: 0 | K45: 0
A48: Project Manager: Cox, Randy
A50: 1056136 | B50: Frontier - Maint SSP Valley (2025-27) | C50: 463995.06 | D50: 251398.53 | E50: 185266.68 | F50: 4170.74 | G50: 6437.21 | H50: 16721.9 | I50: 0 | J50: 0 | K50: 0
A52: 1056282 | B52: ATT - A05AJGW - Coulterville | C52: 354095.06 | D52: 198391.14 | E52: 155703.92 | F52: 0 | G52: 0 | H52: 0 | I52: 0 | J52: 0 | K52: 0
A54: 2051013 | B54: Sprint-Maintenance-Selma | C54: 15432.177 | D54: 0 | E54: 15432.177 | F54: 0 | G54: 0 | H54: 0 | I54: 0 | J54: 0 | K54: 0
A56: 2052056 | B56: Lumen - NAT OSP CENCAL MSA 2022-Selma | C56: 11945.34 | D56: 0 | E56: 2546.11 | F56: 9399.23 | G56: 0 | H56: 0 | I56: 0 | J56: 0 | K56: 0
A58: 2052135 | B58: ATT - 2024 T&M Rates-Valley | C58: 3320 | D58: 0 | E58: 0 | F58: 0 | G58: 0 | H58: 0 | I58: 3320 | J58: 0 | K58: 0
A60: NEDGSUFRS | B60: VZ-Verizon-NED-Fresno | C60: 993.24 | D60: 0 | E60: 0 | F60: 0 | G60: 0 | H60: 0 | I60: 993.24 | J60: 0 | K60: 0
C63: 849780.88 | D63: 449789.67 | E63: 358948.89 | F63: 13569.97 | G63: 6437.21 | H63: 16721.9 | I63: 4313.24 | J63: 0 | K63: 0
A66: Project Manager: Doran, Dennis
A68: 1380049 | B68: Stayton Telephone - Unit Rates | C68: 14569.78 | D68: 14569.78 | E68: 0 | F68: 0 | G68: 0 | H68: 0 | I68: 0 | J68: 0 | K68: 0
A70: 1380050 | B70: Peoples Telephone - Unit Rates | C70: 5963 | D70: 5963 | E70: 0 | F70: 0 | G70: 0 | H70: 0 | I70: 0 | J70: 0 | K70: 0
C73: 20532.78 | D73: 20532.78 | E73: 0 | F73: 0 | G73: 0 | H73: 0 | I73: 0 | J73: 0 | K73: 0
A76: Project Manager: Haskins, Dwayne
A78: 1056144 | B78: Consolidated Communications MSA | C78: 37802.972 | D78: 2292.972 | E78: 35510 | F78: 0 | G78: 0 | H78: 0 | I78: 0 | J78: 0 | K78: 0
